2025-03-01 00:22:05,805 INFO    MainThread:7668 [wandb_setup.py:_flush():67] Current SDK version is 0.19.7
2025-03-01 00:22:05,805 INFO    MainThread:7668 [wandb_setup.py:_flush():67] Configure stats pid to 7668
2025-03-01 00:22:05,805 INFO    MainThread:7668 [wandb_setup.py:_flush():67] Loading settings from C:\Users\DELL\.config\wandb\settings
2025-03-01 00:22:05,805 INFO    MainThread:7668 [wandb_setup.py:_flush():67] Loading settings from c:\Users\DELL\Desktop\Coding\Python\DL\wandb\settings
2025-03-01 00:22:05,805 INFO    MainThread:7668 [wandb_setup.py:_flush():67] Loading settings from environment variables
2025-03-01 00:22:05,806 INFO    MainThread:7668 [wandb_init.py:setup_run_log_directory():647] Logging user logs to c:\Users\DELL\Desktop\Coding\Python\DL\wandb\run-20250301_002205-8nhanl89\logs\debug.log
2025-03-01 00:22:05,806 INFO    MainThread:7668 [wandb_init.py:setup_run_log_directory():648] Logging internal logs to c:\Users\DELL\Desktop\Coding\Python\DL\wandb\run-20250301_002205-8nhanl89\logs\debug-internal.log
2025-03-01 00:22:05,806 INFO    MainThread:7668 [wandb_init.py:monkeypatch_ipython():599] configuring jupyter hooks <wandb.sdk.wandb_init._WandbInit object at 0x000001CE70729D80>
2025-03-01 00:22:05,806 INFO    MainThread:7668 [wandb_init.py:init():761] calling init triggers
2025-03-01 00:22:05,807 INFO    MainThread:7668 [wandb_init.py:init():766] wandb.init called with sweep_config: {}
config: {'_wandb': {}}
2025-03-01 00:22:05,807 INFO    MainThread:7668 [wandb_init.py:init():784] starting backend
2025-03-01 00:22:05,807 INFO    MainThread:7668 [wandb_init.py:init():788] sending inform_init request
2025-03-01 00:22:05,816 INFO    MainThread:7668 [backend.py:_multiprocessing_setup():97] multiprocessing start_methods=spawn, using: spawn
2025-03-01 00:22:05,816 INFO    MainThread:7668 [wandb_init.py:init():803] backend started and connected
2025-03-01 00:22:05,817 INFO    MainThread:7668 [wandb_run.py:_label_probe_notebook():1204] probe notebook
2025-03-01 00:22:05,818 INFO    MainThread:7668 [wandb_init.py:init():896] updated telemetry
2025-03-01 00:22:05,847 INFO    MainThread:7668 [wandb_init.py:init():920] communicating run to backend with 90.0 second timeout
2025-03-01 00:22:10,496 INFO    Thread-11 (wrapped_target):7668 [retry.py:__call__():175] Retry attempt failed:
Traceback (most recent call last):
  File "C:\Users\DELL\AppData\Roaming\Python\Python310\site-packages\urllib3\connection.py", line 198, in _new_conn
    sock = connection.create_connection(
  File "C:\Users\DELL\AppData\Roaming\Python\Python310\site-packages\urllib3\util\connection.py", line 60, in create_connection
    for res in socket.getaddrinfo(host, port, family, socket.SOCK_STREAM):
  File "c:\Users\DELL\.conda\envs\RL\lib\socket.py", line 955, in getaddrinfo
    for res in _socket.getaddrinfo(host, port, family, type, proto, flags):
socket.gaierror: [Errno 11001] getaddrinfo failed

The above exception was the direct cause of the following exception:

Traceback (most recent call last):
  File "C:\Users\DELL\AppData\Roaming\Python\Python310\site-packages\urllib3\connectionpool.py", line 793, in urlopen
    response = self._make_request(
  File "C:\Users\DELL\AppData\Roaming\Python\Python310\site-packages\urllib3\connectionpool.py", line 491, in _make_request
    raise new_e
  File "C:\Users\DELL\AppData\Roaming\Python\Python310\site-packages\urllib3\connectionpool.py", line 467, in _make_request
    self._validate_conn(conn)
  File "C:\Users\DELL\AppData\Roaming\Python\Python310\site-packages\urllib3\connectionpool.py", line 1099, in _validate_conn
    conn.connect()
  File "C:\Users\DELL\AppData\Roaming\Python\Python310\site-packages\urllib3\connection.py", line 616, in connect
    self.sock = sock = self._new_conn()
  File "C:\Users\DELL\AppData\Roaming\Python\Python310\site-packages\urllib3\connection.py", line 205, in _new_conn
    raise NameResolutionError(self.host, self, e) from e
urllib3.exceptions.NameResolutionError: <urllib3.connection.HTTPSConnection object at 0x000001CE75BC8D00>: Failed to resolve 'api.wandb.ai' ([Errno 11001] getaddrinfo failed)

The above exception was the direct cause of the following exception:

Traceback (most recent call last):
  File "C:\Users\DELL\AppData\Roaming\Python\Python310\site-packages\requests\adapters.py", line 486, in send
    resp = conn.urlopen(
  File "C:\Users\DELL\AppData\Roaming\Python\Python310\site-packages\urllib3\connectionpool.py", line 847, in urlopen
    retries = retries.increment(
  File "C:\Users\DELL\AppData\Roaming\Python\Python310\site-packages\urllib3\util\retry.py", line 515, in increment
    raise MaxRetryError(_pool, url, reason) from reason  # type: ignore[arg-type]
urllib3.exceptions.MaxRetryError: HTTPSConnectionPool(host='api.wandb.ai', port=443): Max retries exceeded with url: /graphql (Caused by NameResolutionError("<urllib3.connection.HTTPSConnection object at 0x000001CE75BC8D00>: Failed to resolve 'api.wandb.ai' ([Errno 11001] getaddrinfo failed)"))

During handling of the above exception, another exception occurred:

Traceback (most recent call last):
  File "c:\Users\DELL\.conda\envs\RL\lib\site-packages\wandb\sdk\lib\retry.py", line 134, in __call__
    result = self._call_fn(*args, **kwargs)
  File "c:\Users\DELL\.conda\envs\RL\lib\site-packages\wandb\sdk\internal\internal_api.py", line 398, in execute
    return self.client.execute(*args, **kwargs)  # type: ignore
  File "c:\Users\DELL\.conda\envs\RL\lib\site-packages\wandb\vendor\gql-0.2.0\wandb_gql\client.py", line 52, in execute
    result = self._get_result(document, *args, **kwargs)
  File "c:\Users\DELL\.conda\envs\RL\lib\site-packages\wandb\vendor\gql-0.2.0\wandb_gql\client.py", line 60, in _get_result
    return self.transport.execute(document, *args, **kwargs)
  File "c:\Users\DELL\.conda\envs\RL\lib\site-packages\wandb\sdk\lib\gql_request.py", line 58, in execute
    request = self.session.post(self.url, **post_args)
  File "C:\Users\DELL\AppData\Roaming\Python\Python310\site-packages\requests\sessions.py", line 637, in post
    return self.request("POST", url, data=data, json=json, **kwargs)
  File "C:\Users\DELL\AppData\Roaming\Python\Python310\site-packages\requests\sessions.py", line 589, in request
    resp = self.send(prep, **send_kwargs)
  File "C:\Users\DELL\AppData\Roaming\Python\Python310\site-packages\requests\sessions.py", line 703, in send
    r = adapter.send(request, **kwargs)
  File "C:\Users\DELL\AppData\Roaming\Python\Python310\site-packages\requests\adapters.py", line 519, in send
    raise ConnectionError(e, request=request)
requests.exceptions.ConnectionError: HTTPSConnectionPool(host='api.wandb.ai', port=443): Max retries exceeded with url: /graphql (Caused by NameResolutionError("<urllib3.connection.HTTPSConnection object at 0x000001CE75BC8D00>: Failed to resolve 'api.wandb.ai' ([Errno 11001] getaddrinfo failed)"))
